Workbook

Sheet All Patterns
A1: Category | B1: Pattern | C1: Trigger / When | D1: Sub-Patterns / Notes | E1: Canonical | F1: Variation | G1: Status | H1: Confidence (1-5) | I1: Teach-back Done? | J1: Last Reviewed | K1: Next Review | L1: Ref 1 | M1: Ref 2 | N1: Google | O1: Ref 3 | P1: YouTube Search
A2: DSA | B2: Two Pointers | C2: sorted, palindrome, partition | D2: L/R; same dir; partition | E2: Valid Palindrome (125) | F2: 3Sum (15) | G2: Not Started | L2: https://www.geeksforgeeks.org/two-pointers-technique/ | M2: https://www.educative.io/answers/what-is-the-two-pointer-technique | O2: https://leetcode.com/problems/valid-palindrome/ | P2: https://www.youtube.com/results?search_query=Two+Pointers+pattern
A3: DSA | B3: Sliding Window | C3: substring, longest/shortest | D3: fixed; variable; freq map | E3: Longest Substring (3) | F3: Min Window (76) | G3: Not Started | L3: https://www.geeksforgeeks.org/window-sliding-technique/ | M3: https://www.educative.io/answers/what-is-the-sliding-window-technique | O3: https://leetcode.com/problems/longest-substring-without-repeating-characters/ | P3: https://www.youtube.com/results?search_query=Sliding+Window+pattern
A4: DSA | B4: Fast/Slow | C4: cycles, middle | D4: cycle detect; entry | E4: Linked List Cycle (141) | F4: Cycle II (142) | G4: Not Started | L4: https://www.geeksforgeeks.org/floyds-cycle-finding-algorithm/ | M4: https://cp-algorithms.com/others/tortoise_and_hare.html | O4: https://leetcode.com/problems/linked-list-cycle/ | P4: https://www.youtube.com/results?search_query=Fast%2FSlow+pattern
A5: DSA | B5: Binary Search | C5: sorted, monotonic | D5: left/right bound; answer space | E5: Binary Search (704) | F5: Rotated Search (33) | G5: Not Started | L5: https://cp-algorithms.com/num_methods/binary_search.html | M5: https://www.geeksforgeeks.org/binary-search/ | O5: https://leetcode.com/problems/binary-search/ | P5: https://www.youtube.com/results?search_query=Binary+Search+pattern
A6: DSA | B6: Tree DFS | C6: recursion, subtree | D6: top-down; bottom-up | E6: Max Depth (104) | F6: Validate BST (98) | G6: Not Started | L6: https://www.geeksforgeeks.org/tree-traversals-inorder-preorder-and-postorder/ | M6: https://cp-algorithms.com/graph/depth-first-search.html | O6: https://leetcode.com/problems/maximum-depth-of-binary-tree/ | P6: https://www.youtube.com/results?search_query=Tree+DFS+pattern
A7: DSA | B7: Tree BFS | C7: level traversal | D7: zigzag; multi-source | E7: Level Order (102) | F7: Distance K (863) | G7: Not Started | L7: https://cp-algorithms.com/graph/breadth-first-search.html | M7: https://www.geeksforgeeks.org/level-order-tree-traversal/ | O7: https://leetcode.com/problems/binary-tree-level-order-traversal/ | P7: https://www.youtube.com/results?search_query=Tree+BFS+pattern
A8: DSA | B8: Graph DFS/BFS | C8: components, deps | D8: topo; union-find | E8: Number of Islands (200) | F8: Course Schedule (207) | G8: Not Started | L8: https://cp-algorithms.com/graph/depth-first-search.html | M8: https://cp-algorithms.com/graph/breadth-first-search.html | O8: https://cp-algorithms.com/graph/topological-sort.html | P8: https://www.youtube.com/results?search_query=Graph+DFS%2FBFS+pattern
A9: DSA | B9: Backtracking | C9: generate all | D9: subsets; perms; prune | E9: Subsets (78) | F9: N-Queens (51) | G9: Not Started | L9: https://www.geeksforgeeks.org/backtracking-algorithms/ | M9: https://leetcode.com/problems/subsets/ | O9: https://cp-algorithms.com/graph/backtracking.html | P9: https://www.youtube.com/results?search_query=Backtracking+pattern
A10: DSA | B10: Heap | C10: top-k, merge-k | D10: min/max; 2-heaps | E10: Top K Frequent (347) | F10: Merge K Lists (23) | G10: Not Started | L10: https://cp-algorithms.com/data_structures/heap.html | M10: https://www.geeksforgeeks.org/heap-data-structure/ | O10: https://leetcode.com/problems/top-k-frequent-elements/ | P10: https://www.youtube.com/results?search_query=Heap+pattern
A11: DSA | B11: DP | C11: optimal + overlap | D11: 1D; 2D; knapsack; LIS | E11: Climbing Stairs (70) | F11: Coin Change (322) | G11: Not Started | L11: https://cp-algorithms.com/dynamic_programming/intro-to-dp.html | M11: https://www.geeksforgeeks.org/dynamic-programming/ | O11: https://leetcode.com/problems/climbing-stairs/ | P11: https://www.youtube.com/results?search_query=DP+pattern
A12: DSA | B12: Prefix Sum | C12: range sum, subarray=k | D12: hashmap prefix; 2D | E12: Subarray Sum = K (560) | F12: 2D Range Sum (304) | G12: Not Started | L12: https://cp-algorithms.com/data_structures/fenwick.html | M12: https://www.geeksforgeeks.org/prefix-sum-array-implementation-applications-competitive-programming/ | O12: https://leetcode.com/problems/subarray-sum-equals-k/ | P12: https://www.youtube.com/results?search_query=Prefix+Sum+pattern
A13: DSA | B13: Monotonic Stack | C13: next greater | D13: inc/dec stack | E13: Daily Temps (739) | F13: Histogram (84) | G13: Not Started | L13: https://cp-algorithms.com/data_structures/stack_queue_modification.html | M13: https://www.geeksforgeeks.org/introduction-to-monotonic-stack-data-structure-and-algorithm-tutorials/ | O13: https://leetcode.com/problems/daily-temperatures/ | P13: https://www.youtube.com/results?search_query=Monotonic+Stack+pattern
A14: DSA | B14: Greedy | C14: local→global | D14: intervals; jump | E14: Merge Intervals (56) | F14: Jump Game (55) | G14: Not Started | L14: https://cp-algorithms.com/greedy/greedy.html | M14: https://www.geeksforgeeks.org/greedy-algorithms/ | O14: https://leetcode.com/problems/merge-intervals/ | P14: https://www.youtube.com/results?search_query=Greedy+pattern
A15: Reliability | B15: Timeout | C15: calls hang | D15: add per-call timeout | G15: Not Started | L15: https://learn.microsoft.com/en-us/azure/architecture/patterns/timeout | M15: https://microservices.io/patterns/reliability/timeouts.html | N15: https://www.google.com/search?q=Time+Out+pattern+with+fastapi&sca_esv=4ca364c6bf4cd7e9&sxsrf=ANbL-n6q6s1ksXGCbgL8IR1rh5oaokXbnQ%3A1771783422968&ei=_kSbad7COMGc0PEP49KOmAg&iflsig=AFdpzrgAAAAAaZtTDjN26I7toX_sTjKgpRyKzBp3Puk1&ved=2ahUKEwix0PTP1-2SAxXIrYkEHVjeA_oQ0NsOegQIAxAB&uact=5&sclient=gws-wiz&udm=50&fbs=ADc_l-aN0CWEZBOHjofHoaMMDiKpaEWjvZ2Py1XXV8d8KvlI3vWUtYx0DZdicpfE1faGYemg2KC4yuMPyQlIvlWqq2AtcdVMJmMDffRprXURy79lwU70Lz2dh0euofCmx0cOkSMUN_9xLa1WY5bR54cNlXeNGNTIGEBWBS4AHaEHunITDBubohheJbfr-zPyq37pAUUqNqfD1HmhD39p6KjzK0vACrrg3Q&aep=10&ntc=1&mstk=AUtExfDB1a5Jf3HyuiJGabEeVfxU_O8JrEttUdhFkHylBHASDqsZ1O73mGoSsI1cxCapUOh6mayZRVheygq1icjJp9SDYlJY_XhDJzVYhbO927fpZYEatOYrrnLF7S86ENCea0xg8Wf0uAEcBYcuZ48uZAe7tEIVqWmYnJM6l0ru7pkRtifaXipYlOHsiht2NIg-yqz_CB2v6h3MW-uOuQg2E95eZ8i_eQ4S9jvUlocMFZbr6lHjZHZ9l07UaiDY1HOOHJb_imCQkdNMqhM9OkpNl7PHWqcTZ0gSqm5ImWq4TCOzU9HH9tIEGr16zKvAukUG0quqMGS7bx9k3A&csuir=1&mtid=L0WbaYOULtz8ptQPravB4Q4&atvm=1#sv=CAMSWBozKhFpYy01WGpZQjlJOTJHRTJJTTIONVhqWUI5STkyR0UySU06DlFFcHpTMkVTSUd0emVNIAQqGwoEc3ZpbRIRaWMtNVhqWUI5STkyR0UySU0YATABOAAYByDo__zLBjACOgA | O15: https://martinfowler.com/articles/patterns-of-distributed-systems/timeouts.html | P15: https://www.youtube.com/results?search_query=Timeout+pattern
A16: Reliability | B16: Retry + Backoff | C16: transient failures | D16: exponential retry + jitter | G16: Not Started | L16: https://learn.microsoft.com/en-us/azure/architecture/patterns/retry | M16: https://microservices.io/patterns/reliability/retry.html | O16: https://aws.amazon.com/builders-library/timeouts-retries-and-backoff-with-jitter/ | P16: https://www.youtube.com/results?search_query=Retry+%2B+Backoff+pattern
A17: Reliability | B17: Circuit Breaker | C17: cascading failure | D17: open/half-open state logic | G17: Not Started | L17: https://learn.microsoft.com/en-us/azure/architecture/patterns/circuit-breaker | M17: https://microservices.io/patterns/reliability/circuit-breaker.html | O17: https://martinfowler.com/bliki/CircuitBreaker.html | P17: https://www.youtube.com/results?search_query=Circuit+Breaker+pattern
A18: Reliability | B18: Bulkhead | C18: isolate services | D18: separate worker pools | G18: Not Started | L18: https://learn.microsoft.com/en-us/azure/architecture/patterns/bulkhead | M18: https://martinfowler.com/articles/patterns-of-distributed-systems/bulkheads.html | O18: https://microservices.io/patterns/reliability/bulkhead.html | P18: https://www.youtube.com/results?search_query=Bulkhead+pattern
A19: Reliability | B19: Rate Limiting | C19: protect system | D19: token bucket per tenant | G19: Not Started | L19: https://cloud.google.com/architecture/rate-limiting-strategies-techniques | M19: https://www.nginx.com/blog/rate-limiting-nginx/ | O19: https://en.wikipedia.org/wiki/Token_bucket | P19: https://www.youtube.com/results?search_query=Rate+Limiting+pattern
A20: Reliability | B20: Graceful Degradation | C20: partial failure | D20: fallback model | G20: Not Started | L20: https://martinfowler.com/articles/patterns-of-distributed-systems/graceful-degradation.html | M20: https://learn.microsoft.com/en-us/azure/architecture/guide/design-principles/graceful-degradation | O20: https://www.infoq.com/articles/resilience-patterns/ | P20: https://www.youtube.com/results?search_query=Graceful+Degradation+pattern
A21: Reliability | B21: Load Shedding | C21: overload | D21: reject low priority jobs | G21: Not Started | L21: https://sre.google/sre-book/handling-overload/ | M21: https://cloud.google.com/architecture/handling-overload | O21: https://www.infoq.com/articles/load-shedding/ | P21: https://www.youtube.com/results?search_query=Load+Shedding+pattern
A22: Distributed Workflows | B22: Job / Workflow | C22: long tasks | D22: async job queue | G22: Not Started | L22: https://martinfowler.com/articles/patterns-of-distributed-systems/long-running-request.html | M22: https://learn.microsoft.com/en-us/azure/architecture/patterns/async-request-reply | O22: https://aws.amazon.com/builders-library/background-work/ | P22: https://www.youtube.com/results?search_query=Job+%2F+Workflow+pattern
A23: Distributed Workflows | B23: Idempotency Key | C23: retries happen | D23: prevent duplicate job | G23: Not Started | L23: https://stripe.com/docs/idempotency | M23: https://microservices.io/patterns/communication-style/idempotent-consumer.html | O23: https://docs.aws.amazon.com/apigateway/latest/developerguide/api-gateway-idempotency.html | P23: https://www.youtube.com/results?search_query=Idempotency+Key+pattern
A24: Distributed Workflows | B24: Deduplication | C24: cost control | D24: hash request body | G24: Not Started | L24: https://learn.microsoft.com/en-us/azure/service-bus-messaging/duplicate-detection | M24: https://docs.aws.amazon.com/AWSSimpleQueueService/latest/SQSDeveloperGuide/sqs-deduplication.html | O24: https://cloud.google.com/pubsub/docs/exactly-once-delivery | P24: https://www.youtube.com/results?search_query=Deduplication+pattern
A25: Distributed Workflows | B25: Outbox Pattern | C25: reliable events | D25: DB + async publish | G25: Not Started | L25: https://microservices.io/patterns/data/transactional-outbox.html | M25: https://learn.microsoft.com/en-us/azure/architecture/patterns/transactional-outbox | O25: https://www.confluent.io/blog/transactional-outbox-pattern/ | P25: https://www.youtube.com/results?search_query=Outbox+Pattern+pattern
A26: Distributed Workflows | B26: Saga | C26: multi-step rollback | D26: compensating actions | G26: Not Started | L26: https://microservices.io/patterns/data/saga.html | M26: https://learn.microsoft.com/en-us/azure/architecture/reference-architectures/saga/saga | O26: https://www.confluent.io/blog/saga-pattern-microservices/ | P26: https://www.youtube.com/results?search_query=Saga+pattern
A27: Distributed Workflows | B27: Backpressure | C27: queue overflow | D27: concurrency limits | G27: Not Started | L27: https://learn.microsoft.com/en-us/azure/architecture/patterns/backpressure | M27: https://sre.google/sre-book/handling-overload/ | O27: https://www.reactive-streams.org/ | P27: https://www.youtube.com/results?search_query=Backpressure+pattern
... A59: LLM Safety & Cost | B59: Token Budgets | C59: guardrail | D59: per-tenant cap | G59: Not Started | L59: https://learn.microsoft.com/en-us/azure/ai-services/openai/concepts/tokens | M59: https://platform.openai.com/docs/guides/cost-optimization | O59: https://sre.google/sre-book/capacity-planning/ | P59: https://www.youtube.com/results?search_query=Token+Budgets+pattern
A60: GoF - Creational | B60: Factory | D60: dynamic model selection | G60: Not Started | L60: https://refactoring.guru/design-patterns/factory-method | M60: https://www.geeksforgeeks.org/factory-method-design-pattern-in-python/ | P60: https://www.youtube.com/results?search_query=Factory+pattern
A61: GoF - Creational | B61: Abstract Factory | D61: multi-provider system | G61: Not Started | L61: https://refactoring.guru/design-patterns/abstract-factory | M61: https://www.geeksforgeeks.org/abstract-factory-pattern/ | P61: https://www.youtube.com/results?search_query=Abstract+Factory+pattern
A62: GoF - Creational | B62: Builder | D62: prompt construction | G62: Not Started | L62: https://refactoring.guru/design-patterns/builder | M62: https://www.geeksforgeeks.org/builder-design-pattern/ | P62: https://www.youtube.com/results?search_query=Builder+pattern
A63: GoF - Creational | B63: Singleton | D63: config manager | G63: Not Started | L63: https://refactoring.guru/design-patterns/singleton | M63: https://www.geeksforgeeks.org/singleton-design-pattern/ | P63: https://www.youtube.com/results?search_query=Singleton+pattern
A64: GoF - Creational | B64: Prototype | D64: clone agent config | G64: Not Started | L64: https://refactoring.guru/design-patterns/prototype | M64: https://www.geeksforgeeks.org/prototype-design-pattern/ | P64: https://www.youtube.com/results?search_query=Prototype+pattern
A65: GoF - Structural | B65: Adapter | D65: unify provider interfaces | G65: Not Started | L65: https://refactoring.guru/design-patterns/adapter | M65: https://www.geeksforgeeks.org/adapter-pattern/ | P65: https://www.youtube.com/results?search_query=Adapter+pattern
A66: GoF - Structural | B66: Facade | D66: simplify RAG pipeline | G66: Not Started | L66: https://refactoring.guru/design-patterns/facade | M66: https://www.geeksforgeeks.org/facade-design-pattern/ | P66: https://www.youtube.com/results?search_query=Facade+pattern
A67: GoF - Structural | B67: Decorator | D67: add logging/token tracking | G67: Not Started | L67: https://refactoring.guru/design-patterns/decorator | M67: https://www.geeksforgeeks.org/decorator-pattern/ | P67: https://www.youtube.com/results?search_query=Decorator+pattern
A68: GoF - Structural | B68: Proxy | D68: caching / rate limiting | G68: Not Started | L68: https://refactoring.guru/design-patterns/proxy | M68: https://www.geeksforgeeks.org/proxy-design-pattern/ | P68: https://www.youtube.com/results?search_query=Proxy+pattern
A69: GoF - Structural | B69: Bridge | D69: abstraction vs implementation | G69: Not Started | L69: https://refactoring.guru/design-patterns/bridge | M69: https://www.geeksforgeeks.org/bridge-design-pattern/ | P69: https://www.youtube.com/results?search_query=Bridge+pattern
A70: GoF - Structural | B70: Composite | D70: workflow tree | G70: Not Started | L70: https://refactoring.guru/design-patterns/composite | M70: https://www.geeksforgeeks.org/composite-design-pattern/ | P70: https://www.youtube.com/results?search_query=Composite+pattern
A71: GoF - Behavioral | B71: Strategy | D71: retrieval switching | G71: Not Started | L71: https://refactoring.guru/design-patterns/strategy | M71: https://www.geeksforgeeks.org/strategy-pattern/ | P71: https://www.youtube.com/results?search_query=Strategy+pattern
...

Sheet Dashboard
A1: Master Pattern Library — Dashboard
A3: Today | B3: 2026-02-22
D4: Progress by Category
A5: Total Patterns | B5: =COUNTA('All Patterns'!B:B)-1 -> 77
A6: Not Started | B6: =COUNTIF('All Patterns'!G:G,"Not Started") -> 77 | D6: Category | E6: Mastered | F6: Completed | G6: In Progress | H6: Not Started
A7: In Progress | B7: =COUNTIF('All Patterns'!G:G,"In Progress") -> 0 | D7: API Design | E7: =COUNTIFS('All Patterns'!A:A,D7,'All Patterns'!G:G,"Mastered") -> 0 | F7: =COUNTIFS('All Patterns'!A:A,D7,'All Patterns'!G:G,"Completed") -> 0 | G7: =COUNTIFS('All Patterns'!A:A,D7,'All Patterns'!G:G,"In Progress") -> 0 | H7: =COUNTIFS('All Patterns'!A:A,D7,'All Patterns'!G:G,"Not Started") -> 5
A8: Completed | B8: =COUNTIF('All Patterns'!G:G,"Completed") -> 0 | D8: Agentic | E8: =COUNTIFS('All Patterns'!A:A,D8,'All Patterns'!G:G,"Mastered") -> 0 | F8: =COUNTIFS('All Patterns'!A:A,D8,'All Patterns'!G:G,"Completed") -> 0 | G8: =COUNTIFS('All Patterns'!A:A,D8,'All Patterns'!G:G,"In Progress") -> 0 | H8: =COUNTIFS('All Patterns'!A:A,D8,'All Patterns'!G:G,"Not Started") -> 10
A9: Mastered | B9: =COUNTIF('All Patterns'!G:G,"Mastered") -> 0 | D9: DSA | E9: =COUNTIFS('All Patterns'!A:A,D9,'All Patterns'!G:G,"Mastered") -> 0 | F9: =COUNTIFS('All Patterns'!A:A,D9,'All Patterns'!G:G,"Completed") -> 0 | G9: =COUNTIFS('All Patterns'!A:A,D9,'All Patterns'!G:G,"In Progress") -> 0 | H9: =COUNTIFS('All Patterns'!A:A,D9,'All Patterns'!G:G,"Not Started") -> 13
A10: Mastery % | B10: =(COUNTIF('All Patterns'!G:G,"Mastered")/(COUNTA('All Patterns'!B:B)-1)) -> 0 | D10: Distributed Workflows | E10: =COUNTIFS('All Patterns'!A:A,D10,'All Patterns'!G:G,"Mastered") -> 0 | F10: =COUNTIFS('All Patterns'!A:A,D10,'All Patterns'!G:G,"Completed") -> 0 | G10: =COUNTIFS('All Patterns'!A:A,D10,'All Patterns'!G:G,"In Progress") -> 0 | H10: =COUNTIFS('All Patterns'!A:A,D10,'All Patterns'!G:G,"Not Started") -> 6
A11: Avg Confidence | B11: =AVERAGEIF('All Patterns'!H:H,">0") -> #DIV/0! | D11: GoF - Behavioral | E11: =COUNTIFS('All Patterns'!A:A,D11,'All Patterns'!G:G,"Mastered") -> 0 | F11: =COUNTIFS('All Patterns'!A:A,D11,'All Patterns'!G:G,"Completed") -> 0 | G11: =COUNTIFS('All Patterns'!A:A,D11,'All Patterns'!G:G,"In Progress") -> 0 | H11: =COUNTIFS('All Patterns'!A:A,D11,'All Patterns'!G:G,"Not Started") -> 8
D12: GoF - Creational | E12: =COUNTIFS('All Patterns'!A:A,D12,'All Patterns'!G:G,"Mastered") -> 0 | F12: =COUNTIFS('All Patterns'!A:A,D12,'All Patterns'!G:G,"Completed") -> 0 | G12: =COUNTIFS('All Patterns'!A:A,D12,'All Patterns'!G:G,"In Progress") -> 0 | H12: =COUNTIFS('All Patterns'!A:A,D12,'All Patterns'!G:G,"Not Started") -> 5
D13: GoF - Structural | E13: =COUNTIFS('All Patterns'!A:A,D13,'All Patterns'!G:G,"Mastered") -> 0 | F13: =COUNTIFS('All Patterns'!A:A,D13,'All Patterns'!G:G,"Completed") -> 0 | G13: =COUNTIFS('All Patterns'!A:A,D13,'All Patterns'!G:G,"In Progress") -> 0 | H13: =COUNTIFS('All Patterns'!A:A,D13,'All Patterns'!G:G,"Not Started") -> 6
A14: Legend | D14: LLM Safety & Cost | E14: =COUNTIFS('All Patterns'!A:A,D14,'All Patterns'!G:G,"Mastered") -> 0 | F14: =COUNTIFS('All Patterns'!A:A,D14,'All Patterns'!G:G,"Completed") -> 0 | G14: =COUNTIFS('All Patterns'!A:A,D14,'All Patterns'!G:G,"In Progress") -> 0 | H14: =COUNTIFS('All Patterns'!A:A,D14,'All Patterns'!G:G,"Not Started") -> 5
A15: Mastered = can build + explain + apply in project | D15: Observability | E15: =COUNTIFS('All Patterns'!A:A,D15,'All Patterns'!G:G,"Mastered") -> 0 | F15: =COUNTIFS('All Patterns'!A:A,D15,'All Patterns'!G:G,"Completed") -> 0 | G15: =COUNTIFS('All Patterns'!A:A,D15,'All Patterns'!G:G,"In Progress") -> 0 | H15: =COUNTIFS('All Patterns'!A:A,D15,'All Patterns'!G:G,"Not Started") -> 5
A16: Completed = solved canonical + variation + teach-back | D16: RAG | E16: =COUNTIFS('All Patterns'!A:A,D16,'All Patterns'!G:G,"Mastered") -> 0 | F16: =COUNTIFS('All Patterns'!A:A,D16,'All Patterns'!G:G,"Completed") -> 0 | G16: =COUNTIFS('All Patterns'!A:A,D16,'All Patterns'!G:G,"In Progress") -> 0 | H16: =COUNTIFS('All Patterns'!A:A,D16,'All Patterns'!G:G,"Not Started") -> 7
A17: In Progress = started but not consistent yet | D17: Reliability | E17: =COUNTIFS('All Patterns'!A:A,D17,'All Patterns'!G:G,"Mastered") -> 0 | F17: =COUNTIFS('All Patterns'!A:A,D17,'All Patterns'!G:G,"Completed") -> 0 | G17: =COUNTIFS('All Patterns'!A:A,D17,'All Patterns'!G:G,"In Progress") -> 0 | H17: =COUNTIFS('All Patterns'!A:A,D17,'All Patterns'!G:G,"Not Started") -> 7
